#VRML_SIM R2019a utf8
WorldInfo {
}
Viewpoint {
  orientation 0.9947076457769206 0.10207190572268025 -0.011748425216876114 6.0324451449071494
  position 0.27194434075279994 0.3218167909117619 1.1250373208091335
}
TexturedBackground {
}
TexturedBackgroundLight {
}
Floor {
}
Robot {
  translation 0 0.075 0
  children [
    DEF G_box Group {
      children [
        DEF ROBOD_BODY Shape {
          appearance PBRAppearance {
            baseColor 0.6431372549019608 0 0
            roughness 1
            metalness 0
          }
          geometry DEF G_BODY Box {
            size 0.25 0.07 0.1
          }
        }
        Transform {
          translation 0.09 -0.056 0
          children [
            Shape {
              appearance PBRAppearance {
              }
              geometry Sphere {
                radius 0.02
              }
            }
          ]
        }
      ]
    }
    DEF WHEEL1_JOINT HingeJoint {
      jointParameters HingeJointParameters {
        axis 0 0 1
        anchor -0.05 0 0.06
      }
      device [
        PositionSensor {
          name "encoder"
        }
        RotationalMotor {
          name "motor_righ"
          maxTorque 0.4903
        }
      ]
      endPoint DEF WHEEL1 Solid {
        translation -0.049970226576958314 0.00026277683203586137 0.059997289048045334
        rotation -0.7156240391787234 0.49390470025463923 -0.49390321077707505 1.899325885168314
        children [
          DEF SH_WELL_SHApe Shape {
            appearance PBRAppearance {
              baseColor 0.9333333333333333 0.9333333333333333 0.9254901960784314
              roughness 1
              metalness 0
            }
            geometry DEF G_WHEEL Cylinder {
              height 0.02
              radius 0.075
            }
          }
        ]
        boundingObject USE G_WHEEL
        physics Physics {
        }
      }
    }
    DEF WHELL_2 HingeJoint {
      jointParameters HingeJointParameters {
        axis 0 0 1
        anchor -0.05 0 -0.06
      }
      device [
        RotationalMotor {
          name "motor_left"
          maxTorque 0.4903
        }
      ]
      endPoint DEF WHELL2 Solid {
        translation -0.04966555121706661 -0.0023198927430729543 -0.059994205222215775
        rotation 0.9863622717627574 0.11877014430361633 0.11394350207497855 1.6213368479690233
        children [
          Shape {
            appearance PBRAppearance {
              baseColor 0.9333333333333333 0.9333333333333333 0.9254901960784314
              roughness 1
              metalness 0
            }
            geometry USE G_WHEEL
          }
        ]
        name "solid(1)"
        boundingObject USE SH_WELL_SHApe
        physics Physics {
        }
      }
    }
    DistanceSensor {
      translation 0.125 0 0
      children [
        Shape {
          appearance PBRAppearance {
            baseColor 0.9882352941176471 0.9137254901960784 0.30980392156862746
          }
          geometry Box {
            size 0.02 0.01 0.01
          }
        }
      ]
      name "distance_sensor"
      lookupTable [
        0 0 0
        0.04 0 0
        11 4 0
      ]
      resolution 0.03
    }
  ]
  boundingObject USE G_box
  physics Physics {
    mass 1
  }
  controller "u2_exam_ventura_cesar"
}
Solid {
  translation 0.20999999999999996 0.05 0
  rotation 1 0 0 6.283185307179586
  children [
    DEF D_OBSTACLE Shape {
      appearance PBRAppearance {
        baseColor 0.6784313725490196 0.4980392156862745 0.6588235294117647
      }
      geometry Box {
        size 0.1 0.1 0.1
      }
    }
  ]
  boundingObject USE D_OBSTACLE
}
